<?xml version="1.0"?>
<sdf version="1.5">
  <model name="parrot_bebop_2">
    <static>false</static>
    <pose>0 0 0.062656 0 0 0</pose>

    <!-- Main link -->
    <link name="body">
      <pose frame=''>0 0 0 0 -0 0</pose>
      <!-- Inertial properties of the model -->
      <inertial>
        <pose frame=''>0 0 0 0 -0 0</pose>
        <mass>0.503</mass> <!-- kg -->
        <inertia> <!-- kg.m^2 -->
          <ixx>1.805e-3</ixx>
          <ixy>-8.619e-7</ixy>
          <iyy>1.764e-3</iyy>
          <ixz>1.555e-5</ixz>
          <iyz>3.595e-7</iyz>
          <izz>3.328e-3</izz>
        </inertia>
        <pose>0 0 0 0 0 0</pose>
      </inertial>

      <!-- Collision properties of the model -->
      <collision name="body_inertia_collision">
        <pose>-0.00424 0.00014 -0.00595 0 0 0</pose>
        <geometry>
          <box><size>0.316618 0.330564 0.089582</size></box>
        </geometry>
        <max_contacts>10</max_contacts>
        <surface>
          <bounce>
            <restitution_coefficient>0.828</restitution_coefficient>
            <threshold>0</threshold>
          </bounce>
          <friction>
            <ode>
              <mu>10</mu>
              <mu2>5</mu2>
              <fdir1>0 0 0</fdir1>
              <slip1>0.0</slip1>
              <slip2>0.0</slip2>
            </ode>
          </friction>
          <contact>
            <ode>
              <kp>10000.0</kp>
              <kd>10.0</kd>
              <max_vel>0.01</max_vel>
              <min_depth>0</min_depth>
            </ode>
          </contact>
        </surface>
      </collision>

      <!-- Visual representation of the model -->
      <visual name="body_inertia_visual">
        <pose frame=''>0 0 0 0 -0 0</pose>
        <geometry>
          <mesh>
              <uri>model://parrot_bebop_2/meshes/hull.dae</uri>
          </mesh>
        </geometry>
      </visual>      
    </link>

      <link name='propeller_rr'>
        <pose frame=''>-0.09035 -0.11423 -0.00501 0 0 0</pose>
        <inertial>
          <pose frame=''>0 0 0 0 -0 0</pose>
          <mass>0.005</mass>
          <inertia>
            <ixx>9.75e-07</ixx>
            <ixy>0</ixy>
            <ixz>0</ixz>
            <iyy>4.17041e-05</iyy>
            <iyz>0</iyz>
            <izz>4.26041e-05</izz>
          </inertia>
        </inertial>
        <!-- collision -->
        <collision name='propeller_rr_collision'>
          <pose frame=''>0 0 0 0 -0 0</pose>
          <geometry>
            <cylinder>
              <length>0.003</length>
              <radius>0.8</radius>
            </cylinder>
          </geometry>
          <surface>
            <contact>
              <ode/>
            </contact>
            <friction>
              <ode/>
            </friction>
          </surface>
        </collision>
        <!-- Visual representation of the rear right propeller -->
        <visual name="propeller_rr_visual">
          <pose frame=''>0 0 0 0 -0 0</pose>
          <geometry>
            <mesh>
              <uri>model://parrot_bebop_2/meshes/propeller_rr.dae</uri>
            </mesh>
          </geometry>
        </visual>
      </link>

      <joint name='propeller_rr_joint' type='revolute'>
        <child>propeller_rr</child>
        <parent>body</parent>
        <axis>
          <xyz>0 0 1</xyz>
          <limit>
            <lower>-1e+16</lower>
            <upper>1e+16</upper>
          </limit>
          <dynamics>
            <spring_reference>0</spring_reference>
            <spring_stiffness>0</spring_stiffness>
          </dynamics>
          <use_parent_model_frame>1</use_parent_model_frame>
        </axis>
      </joint>

      <link name='propeller_rl'>
        <pose frame=''>-0.09035 0.11452 -0.00501 0 0 0</pose>
        <inertial>
          <pose frame=''>0 0 0 0 -0 0</pose>
          <mass>0.005</mass>
          <inertia>
            <ixx>9.75e-07</ixx>
            <ixy>0</ixy>
            <ixz>0</ixz>
            <iyy>4.17041e-05</iyy>
            <iyz>0</iyz>
            <izz>4.26041e-05</izz>
          </inertia>
        </inertial>
        <!-- collision -->
        <collision name='propeller_rl_collision'>
          <pose frame=''>0 0 0 0 -0 0</pose>
          <geometry>
            <cylinder>
              <length>0.003</length>
              <radius>0.8</radius>
            </cylinder>
          </geometry>
          <surface>
            <contact>
              <ode/>
            </contact>
            <friction>
              <ode/>
            </friction>
          </surface>
        </collision>
        <!-- Visual representation of the rear right propeller -->
        <visual name="propeller_rl_visual">
          <pose frame=''>0 0 0 0 -0 0</pose>
          <geometry>
            <mesh>
              <uri>model://parrot_bebop_2/meshes/propeller_rl.dae</uri>
            </mesh>
          </geometry>
        </visual>
      </link>

      <joint name='propeller_rl_joint' type='revolute'>
        <child>propeller_rl</child>
        <parent>body</parent>
        <axis>
          <xyz>0 0 1</xyz>
          <limit>
            <lower>-1e+16</lower>
            <upper>1e+16</upper>
          </limit>
          <dynamics>
            <spring_reference>0</spring_reference>
            <spring_stiffness>0</spring_stiffness>
          </dynamics>
          <use_parent_model_frame>1</use_parent_model_frame>
        </axis>
      </joint>

      <link name='propeller_fr'>
        <pose frame=''>0.08456 -0.11435 -0.00501 0 0 0</pose>
        <inertial>
          <pose frame=''>0 0 0 0 -0 0</pose>
          <mass>0.005</mass>
          <inertia>
            <ixx>9.75e-07</ixx>
            <ixy>0</ixy>
            <ixz>0</ixz>
            <iyy>4.17041e-05</iyy>
            <iyz>0</iyz>
            <izz>4.26041e-05</izz>
          </inertia>
        </inertial>
        <!-- collision -->
        <collision name='propeller_fr_collision'>
          <pose frame=''>0 0 0 0 -0 0</pose>
          <geometry>
            <cylinder>
              <length>0.003</length>
              <radius>0.8</radius>
            </cylinder>
          </geometry>
          <surface>
            <contact>
              <ode/>
            </contact>
            <friction>
              <ode/>
            </friction>
          </surface>
        </collision>
        <!-- Visual representation of the rear right propeller -->
        <visual name="propeller_fr_visual">
          <pose frame=''>0 0 0 0 -0 0</pose>
          <geometry>
            <mesh>
              <uri>model://parrot_bebop_2/meshes/propeller_fr.dae</uri>
            </mesh>
          </geometry>
        </visual>
      </link>

      <joint name='propeller_fr_joint' type='revolute'>
        <child>propeller_fr</child>
        <parent>body</parent>
        <axis>
          <xyz>0 0 1</xyz>
          <limit>
            <lower>-1e+16</lower>
            <upper>1e+16</upper>
          </limit>
          <dynamics>
            <spring_reference>0</spring_reference>
            <spring_stiffness>0</spring_stiffness>
          </dynamics>
          <use_parent_model_frame>1</use_parent_model_frame>
        </axis>
      </joint>

      <link name='propeller_fl'>
        <pose frame=''>0.08456 0.11463 -0.00501 0 0 0</pose>
        <inertial>
          <pose frame=''>0 0 0 0 -0 0</pose>
          <mass>0.005</mass>
          <inertia>
            <ixx>9.75e-07</ixx>
            <ixy>0</ixy>
            <ixz>0</ixz>
            <iyy>4.17041e-05</iyy>
            <iyz>0</iyz>
            <izz>4.26041e-05</izz>
          </inertia>
        </inertial>
        <!-- collision -->
        <collision name='propeller_fl_collision'>
          <pose frame=''>0 0 0 0 -0 0</pose>
          <geometry>
            <cylinder>
              <length>0.003</length>
              <radius>0.8</radius>
            </cylinder>
          </geometry>
          <surface>
            <contact>
              <ode/>
            </contact>
            <friction>
              <ode/>
            </friction>
          </surface>
        </collision>
        <!-- Visual representation of the rear right propeller -->
        <visual name="propeller_fl_visual">
          <pose frame=''>0 0 0 0 -0 0</pose>
          <geometry>
            <mesh>
              <uri>model://parrot_bebop_2/meshes/propeller_fl.dae</uri>
            </mesh>
          </geometry>
        </visual>
      </link>

      <joint name='propeller_fl_joint' type='revolute'>
        <child>propeller_fl</child>
        <parent>body</parent>
        <axis>
          <xyz>0 0 1</xyz>
          <limit>
            <lower>-1e+16</lower>
            <upper>1e+16</upper>
          </limit>
          <dynamics>
            <spring_reference>0</spring_reference>
            <spring_stiffness>0</spring_stiffness>
          </dynamics>
          <use_parent_model_frame>1</use_parent_model_frame>
        </axis>
      </joint>
  </model>
</sdf>
